Workbook
Name Dilimleyici_Cinsiyet: #N/A
Name Dilimleyici_Departman: #N/A
Name Dilimleyici_Lokasyon: #N/A
Name Dilimleyici_Yaka_Tipi: #N/A

Sheet 01_Personel_Verisi
A1: Sicil No | B1: Ad Soyad | C1: Cinsiyet | D1: Doğum Tarihi | E1: Yaş | F1: Medeni Durum | G1: Çocuk Sayısı | H1: Eğitim Durumu | I1: Departman | J1: Pozisyon | K1: Kademe | L1: Yaka Tipi | M1: Yönetici | N1: Lokasyon | O1: İşe Giriş Tarihi | P1: İşe Çıkış Tarihi | Q1: Çıkış Nedeni | R1: SGK Çıkış Kodu | S1: Durum | T1: Brüt Maaş | U1: Prim | V1: Fazla Mesai (Saat) | W1: SGK Gün Sayısı | X1: Eksik Gün Kodu | Y1: Rapor Gün Sayısı | Z1: Kullanılan Yıllık İzin | AA1: Ücretsiz İzin Gün | AB1: Devamsızlık Gün | AC1: Performans Notu | AD1: Eğitim Saati | AE1: Başvuru Kaynağı | AG1: Kıdem Yılı | AH1: Yaş Aralığı | AI1: Kıdem Aralığı | AJ1: İşe giriş yılı | AK1: Çıkış Yıl
A2: PER0001 | B2: Selin Kara | C2: Kadın | D2: 35528 | E2: 29 | F2: Bekar | G2: 0 | H2: Lisans | I2: Üretim & Operasyon | J2: Operatör | K2: Junior | L2: Mavi Yaka | M2: Üretim & Operasyon Müdürü | N2: İstanbul Merkez | O2: 46022 | P2: 46139 | Q2: Sağlık Sebepleri | R2: 3 | S2: Pasif | T2: 24800 | U2: 0 | V2: 30 | W2: 30 | X2: - | Y2: 0 | Z2: 0 | AA2: 0 | AB2: 0 | AC2: 1 | AD2: 11 | AE2: LinkedIn | AG2: =DATEDIF(O2,TODAY(),"Y") -> 0 | AH2: {=_xlfn.IFS(E2>49,"50+",E2>39,"40-49",E2>29,"30-39",E2>19,"20-29")} -> 20-29 | AI2: {=_xlfn.IFS(AG2>10,"10+",AG2>4,"5-10 YIL",AG2>2,"3-5 YIL",AG2>0.9,"1-3 YIL",AG2<1,"0-1 YIL")} -> 0-1 YIL | AJ2: =YEAR(O2) -> 2025 | AK2: =YEAR(P2) -> 2026
A3: PER0002 | B3: Hüseyin Çetin | C3: Erkek | D3: 33854 | E3: 34 | F3: Evli | G3: 1 | H3: Lisans | I3: Üretim & Operasyon | J3: Takım Lideri | K3: Senior | L3: Mavi Yaka | M3: Üretim & Operasyon Müdürü | N3: İzmir Merkez | O3: 43344 | P3: 45737 | Q3: İstifa (Kariyer Değişikliği) | R3: 4 | S3: Pasif | T3: 41100 | U3: 0 | V3: 35 | W3: 30 | X3: - | Y3: 0 | Z3: 14 | AA3: 0 | AB3: 0 | AC3: 3 | AD3: 9 | AE3: LinkedIn | AG3: =DATEDIF(O3,TODAY(),"Y") -> 7 | AH3: {=_xlfn.IFS(E3>49,"50+",E3>39,"40-49",E3>29,"30-39",E3>19,"20-29")} -> 30-39 | AI3: {=_xlfn.IFS(AG3>10,"10+",AG3>4,"5-10 YIL",AG3>2,"3-5 YIL",AG3>0.9,"1-3 YIL",AG3<1,"0-1 YIL")} -> 5-10 YIL | AJ3: =YEAR(O3) -> 2018 | AK3: =YEAR(P3) -> 2025
A4: PER0003 | B4: Mustafa Kaya | C4: Erkek | D4: 36080 | E4: 28 | F4: Bekar | G4: 0 | H4: Lisans | I4: Üretim & Operasyon | J4: Operatör | K4: Junior | L4: Mavi Yaka | M4: Üretim & Operasyon Müdürü | N4: İstanbul Merkez | O4: 45647 | P4: - | Q4: - | R4: - | S4: Aktif | T4: 28400 | U4: 0 | V4: 40 | W4: 27 | X4: 01-Istirahat | Y4: 3 | Z4: 6 | AA4: 0 | AB4: 0 | AC4: 5 | AD4: 32 | AE4: Kariyer.net | AG4: =DATEDIF(O4,TODAY(),"Y") -> 1 | AH4: {=_xlfn.IFS(E4>49,"50+",E4>39,"40-49",E4>29,"30-39",E4>19,"20-29")} -> 20-29 | AI4: {=_xlfn.IFS(AG4>10,"10+",AG4>4,"5-10 YIL",AG4>2,"3-5 YIL",AG4>0.9,"1-3 YIL",AG4<1,"0-1 YIL")} -> 1-3 YIL | AJ4: =YEAR(O4) -> 2024 | AK4: =YEAR(P4) -> #VALUE!
A5: PER0004 | B5: Merve Aydın | C5: Kadın | D5: 36008 | E5: 28 | F5: Evli | G5: 0 | H5: Lisans | I5: Satış & Pazarlama | J5: Satış Temsilcisi | K5: Junior | L5: Beyaz Yaka | M5: Satış & Pazarlama Müdürü | N5: İstanbul Merkez | O5: 46038 | P5: - | Q5: - | R5: - | S5: Aktif | T5: 34900 | U5: 9900 | V5: 4 | W5: 27 | X5: 01-Istirahat | Y5: 3 | Z5: 0 | AA5: 0 | AB5: 0 | AC5: 4 | AD5: 20 | AE5: Kariyer.net | AG5: =DATEDIF(O5,TODAY(),"Y") -> 0 | AH5: {=_xlfn.IFS(E5>49,"50+",E5>39,"40-49",E5>29,"30-39",E5>19,"20-29")} -> 20-29 | AI5: {=_xlfn.IFS(AG5>10,"10+",AG5>4,"5-10 YIL",AG5>2,"3-5 YIL",AG5>0.9,"1-3 YIL",AG5<1,"0-1 YIL")} -> 0-1 YIL | AJ5: =YEAR(O5) -> 2026 | AK5: =YEAR(P5) -> #VALUE!
A6: PER0005 | B6: Fatma Öztürk | C6: Kadın | D6: 37316 | E6: 24 | F6: Bekar | G6: 0 | H6: Lisans | I6: Üretim & Operasyon | J6: Operatör | K6: Junior | L6: Mavi Yaka | M6: Üretim & Operasyon Müdürü | N6: Gebze Fabrika | O6: 46169 | P6: - | Q6: - | R6: - | S6: Aktif | T6: 26200 | U6: 0 | V6: 18 | W6: 29 | X6: 01-Istirahat | Y6: 1 | Z6: 0 | AA6: 0 | AB6: 0 | AC6: 3 | AD6: 8 | AE6: Kariyer.net | AG6: =DATEDIF(O6,TODAY(),"Y") -> 0 | AH6: {=_xlfn.IFS(E6>49,"50+",E6>39,"40-49",E6>29,"30-39",E6>19,"20-29")} -> 20-29 | AI6: {=_xlfn.IFS(AG6>10,"10+",AG6>4,"5-10 YIL",AG6>2,"3-5 YIL",AG6>0.9,"1-3 YIL",AG6<1,"0-1 YIL")} -> 0-1 YIL | AJ6: =YEAR(O6) -> 2026 | AK6: =YEAR(P6) -> #VALUE!
A7: PER0006 | B7: Mustafa Çetin | C7: Erkek | D7: 29557 | E7: 46 | F7: Evli | G7: 1 | H7: Lisans | I7: Finans & Muhasebe | J7: Mali İşler Uzmanı | K7: Senior | L7: Beyaz Yaka | M7: Finans & Muhasebe Müdürü | N7: İstanbul Merkez | O7: 43082 | P7: - | Q7: - | R7: - | S7: Aktif | T7: 62400 | U7: 8600 | V7: 3 | W7: 28 | X7: 01-Istirahat | Y7: 2 | Z7: 9 | AA7: 0 | AB7: 0 | AC7: 2 | AD7: 8 | AE7: Şirket Web Sitesi | AG7: =DATEDIF(O7,TODAY(),"Y") -> 8 | AH7: {=_xlfn.IFS(E7>49,"50+",E7>39,"40-49",E7>29,"30-39",E7>19,"20-29")} -> 40-49 | AI7: {=_xlfn.IFS(AG7>10,"10+",AG7>4,"5-10 YIL",AG7>2,"3-5 YIL",AG7>0.9,"1-3 YIL",AG7<1,"0-1 YIL")} -> 5-10 YIL | AJ7: =YEAR(O7) -> 2017 | AK7: =YEAR(P7) -> #VALUE!
A8: PER0007 | B8: İrem Çetin | C8: Kadın | D8: 38272 | E8: 22 | F8: Evli | G8: 1 | H8: Lisans | I8: Üretim & Operasyon | J8: Operatör | K8: Junior | L8: Mavi Yaka | M8: Üretim & Operasyon Müdürü | N8: İstanbul Merkez | O8: 45292 | P8: 45695 | Q8: İstifa (Kariyer Değişikliği) | R8: 4 | S8: Pasif | T8: 26500 | U8: 0 | V8: 21 | W8: 30 | X8: - | Y8: 0 | Z8: 0 | AA8: 0 | AB8: 0 | AC8: 5 | AD8: 38 | AE8: Kariyer.net | AG8: =DATEDIF(O8,TODAY(),"Y") -> 2 | AH8: {=_xlfn.IFS(E8>49,"50+",E8>39,"40-49",E8>29,"30-39",E8>19,"20-29")} -> 20-29 | AI8: {=_xlfn.IFS(AG8>10,"10+",AG8>4,"5-10 YIL",AG8>2,"3-5 YIL",AG8>0.9,"1-3 YIL",AG8<1,"0-1 YIL")} -> 1-3 YIL | AJ8: =YEAR(O8) -> 2024 | AK8: =YEAR(P8) -> 2025
A9: PER0008 | B9: Burak Öztürk | C9: Erkek | D9: 25395 | E9: 57 | F9: Evli | G9: 3 | H9: Lisans | I9: Üretim & Operasyon | J9: Üretim Müdürü | K9: Manager | L9: Beyaz Yaka | M9: Genel Müdür | N9: İstanbul Merkez | O9: 43068 | P9: - | Q9: - | R9: - | S9: Aktif | T9: 104100 | U9: 0 | V9: 7 | W9: 27 | X9: 02-Ucretsiz Izin | Y9: 0 | Z9: 5 | AA9: 3 | AB9: 0 | AC9: 3 | AD9: 17 | AE9: Referans | AG9: =DATEDIF(O9,TODAY(),"Y") -> 8 | AH9: {=_xlfn.IFS(E9>49,"50+",E9>39,"40-49",E9>29,"30-39",E9>19,"20-29")} -> 50+ | AI9: {=_xlfn.IFS(AG9>10,"10+",AG9>4,"5-10 YIL",AG9>2,"3-5 YIL",AG9>0.9,"1-3 YIL",AG9<1,"0-1 YIL")} -> 5-10 YIL | AJ9: =YEAR(O9) -> 2017 | AK9: =YEAR(P9) -> #VALUE!
A10: PER0009 | B10: İrem Yıldız | C10: Kadın | D10: 29422 | E10: 46 | F10: Bekar | G10: 0 | H10: Yüksek Lisans | I10: Üretim & Operasyon | J10: Takım Lideri | K10: Senior | L10: Mavi Yaka | M10: Üretim & Operasyon Müdürü | N10: İstanbul Merkez | O10: 43855 | P10: - | Q10: - | R10: - | S10: Aktif | T10: 44700 | U10: 0 | V10: 20 | W10: 30 | X10: - | Y10: 0 | Z10: 6 | AA10: 0 | AB10: 0 | AC10: 3 | AD10: 8 | AE10: Kariyer.net | AG10: =DATEDIF(O10,TODAY(),"Y") -> 6 | AH10: {=_xlfn.IFS(E10>49,"50+",E10>39,"40-49",E10>29,"30-39",E10>19,"20-29")} -> 40-49 | AI10: {=_xlfn.IFS(AG10>10,"10+",AG10>4,"5-10 YIL",AG10>2,"3-5 YIL",AG10>0.9,"1-3 YIL",AG10<1,"0-1 YIL")} -> 5-10 YIL | AJ10: =YEAR(O10) -> 2020 | AK10: =YEAR(P10) -> #VALUE!
A11: PER0010 | B11: Furkan Çelik | C11: Erkek | D11: 32951 | E11: 36 | F11: Evli | G11: 0 | H11: Önlisans | I11: Finans & Muhasebe | J11: Mali İşler Uzmanı | K11: Senior | L11: Beyaz Yaka | M11: Finans & Muhasebe Müdürü | N11: Ankara Merkez | O11: 41853 | P11: - | Q11: - | R11: - | S11: Aktif | T11: 65000 | U11: 5900 | V11: 3 | W11: 30 | X11: - | Y11: 0 | Z11: 5 | AA11: 0 | AB11: 0 | AC11: 3 | AD11: 4 | AE11: Kariyer.net | AG11: =DATEDIF(O11,TODAY(),"Y") -> 11 | AH11: {=_xlfn.IFS(E11>49,"50+",E11>39,"40-49",E11>29,"30-39",E11>19,"20-29")} -> 30-39 | AI11: {=_xlfn.IFS(AG11>10,"10+",AG11>4,"5-10 YIL",AG11>2,"3-5 YIL",AG11>0.9,"1-3 YIL",AG11<1,"0-1 YIL")} -> 10+ | AJ11: =YEAR(O11) -> 2014 | AK11: =YEAR(P11) -> #VALUE!
A12: PER0011 | B12: Furkan Aslan | C12: Erkek | D12: 37027 | E12: 25 | F12: Evli | G12: 1 | H12: Lisans | I12: Finans & Muhasebe | J12: Muhasebe Elemanı | K12: Junior | L12: Beyaz Yaka | M12: Finans & Muhasebe Müdürü | N12: İstanbul Merkez | O12: 46039 | P12: - | Q12: - | R12: - | S12: Aktif | T12: 37000 | U12: 0 | V12: 5 | W12: 29 | X12: 02-Ucretsiz Izin | Y12: 0 | Z12: 0 | AA12: 1 | AB12: 0 | AC12: 3 | AD12: 9 | AE12: Kariyer.net | AG12: =DATEDIF(O12,TODAY(),"Y") -> 0 | AH12: {=_xlfn.IFS(E12>49,"50+",E12>39,"40-49",E12>29,"30-39",E12>19,"20-29")} -> 20-29 | AI12: {=_xlfn.IFS(AG12>10,"10+",AG12>4,"5-10 YIL",AG12>2,"3-5 YIL",AG12>0.9,"1-3 YIL",AG12<1,"0-1 YIL")} -> 0-1 YIL | AJ12: =YEAR(O12) -> 2026 | AK12: =YEAR(P12) -> #VALUE!
A13: PER0012 | B13: Hasan Yılmaz | C13: Erkek | D13: 37998 | E13: 22 | F13: Evli | G13: 1 | H13: Lisans | I13: Üretim & Operasyon | J13: Operatör | K13: Junior | L13: Mavi Yaka | M13: Üretim & Operasyon Müdürü | N13: Bursa Merkez | O13: 44859 | P13: - | Q13: - | R13: - | S13: Aktif | T13: 25100 | U13: 0 | V13: 15 | W13: 30 | X13: - | Y13: 0 | Z13: 7 | AA13: 0 | AB13: 0 | AC13: 3 | AD13: 4 | AE13: Danışmanlık Firması | AG13: =DATEDIF(O13,TODAY(),"Y") -> 3 | AH13: {=_xlfn.IFS(E13>49,"50+",E13>39,"40-49",E13>29,"30-39",E13>19,"20-29")} -> 20-29 | AI13: {=_xlfn.IFS(AG13>10,"10+",AG13>4,"5-10 YIL",AG13>2,"3-5 YIL",AG13>0.9,"1-3 YIL",AG13<1,"0-1 YIL")} -> 3-5 YIL | AJ13: =YEAR(O13) -> 2022 | AK13: =YEAR(P13) -> #VALUE!
A14: PER0013 | B14: Selin Şahin | C14: Kadın | D14: 35295 | E14: 30 | F14: Evli | G14: 0 | H14: Lisans | I14: Üretim & Operasyon | J14: Takım Lideri | K14: Senior | L14: Mavi Yaka | M14: Üretim & Operasyon Müdürü | N14: İstanbul Merkez | O14: 42234 | P14: - | Q14: - | R14: - | S14: Aktif | T14: 40900 | U14: 0 | V14: 36 | W14: 30 | X14: - | Y14: 0 | Z14: 7 | AA14: 0 | AB14: 0 | AC14: 3 | AD14: 17 | AE14: Kariyer.net | AG14: =DATEDIF(O14,TODAY(),"Y") -> 10 | AH14: {=_xlfn.IFS(E14>49,"50+",E14>39,"40-49",E14>29,"30-39",E14>19,"20-29")} -> 30-39 | AI14: {=_xlfn.IFS(AG14>10,"10+",AG14>4,"5-10 YIL",AG14>2,"3-5 YIL",AG14>0.9,"1-3 YIL",AG14<1,"0-1 YIL")} -> 5-10 YIL | AJ14: =YEAR(O14) -> 2015 | AK14: =YEAR(P14) -> #VALUE!
A15: PER0014 | B15: Gamze Demir | C15: Kadın | D15: 35783 | E15: 29 | F15: Evli | G15: 1 | H15: Önlisans | I15: Satış & Pazarlama | J15: Satış Temsilcisi | K15: Junior | L15: Beyaz Yaka | M15: Satış & Pazarlama Müdürü | N15: İstanbul Merkez | O15: 44936 | P15: - | Q15: - | R15: - | S15: Aktif | T15: 31000 | U15: 0 | V15: 0 | W15: 27 | X15: 02-Ucretsiz Izin | Y15: 0 | Z15: 5 | AA15: 3 | AB15: 0 | AC15: 3 | AD15: 18 | AE15: LinkedIn | AG15: =DATEDIF(O15,TODAY(),"Y") -> 3 | AH15: {=_xlfn.IFS(E15>49,"50+",E15>39,"40-49",E15>29,"30-39",E15>19,"20-29")} -> 20-29 | AI15: {=_xlfn.IFS(AG15>10,"10+",AG15>4,"5-10 YIL",AG15>2,"3-5 YIL",AG15>0.9,"1-3 YIL",AG15<1,"0-1 YIL")} -> 3-5 YIL | AJ15: =YEAR(O15) -> 2023 | AK15: =YEAR(P15) -> #VALUE!
A16: PER0015 | B16: Burak Doğan | C16: Erkek | D16: 36631 | E16: 26 | F16: Evli | G16: 1 | H16: Lisans | I16: Satış & Pazarlama | J16: Satış Temsilcisi | K16: Junior | L16: Beyaz Yaka | M16: Satış & Pazarlama Müdürü | N16: İstanbul Merkez | O16: 44724 | P16: - | Q16: - | R16: - | S16: Aktif | T16: 35000 | U16: 12000 | V16: 5 | W16: 30 | X16: - | Y16: 0 | Z16: 2 | AA16: 0 | AB16: 0 | AC16: 3 | AD16: 6 | AE16: LinkedIn | AG16: =DATEDIF(O16,TODAY(),"Y") -> 4 | AH16: {=_xlfn.IFS(E16>49,"50+",E16>39,"40-49",E16>29,"30-39",E16>19,"20-29")} -> 20-29 | AI16: {=_xlfn.IFS(AG16>10,"10+",AG16>4,"5-10 YIL",AG16>2,"3-5 YIL",AG16>0.9,"1-3 YIL",AG16<1,"0-1 YIL")} -> 3-5 YIL | AJ16: =YEAR(O16) -> 2022 | AK16: =YEAR(P16) -> #VALUE!
A17: PER0016 | B17: Kübra Özdemir | C17: Kadın | D17: 36411 | E17: 27 | F17: Bekar | G17: 0 | H17: Önlisans | I17: Üretim & Operasyon | J17: Operatör | K17: Junior | L17: Mavi Yaka | M17: Üretim & Operasyon Müdürü | N17: Ankara Merkez | O17: 44842 | P17: - | Q17: - | R17: - | S17: Aktif | T17: 28500 | U17: 0 | V17: 14 | W17: 30 | X17: - | Y17: 0 | Z17: 11 | AA17: 0 | AB17: 0 | AC17: 2 | AD17: 15 | AE17: LinkedIn | AG17: =DATEDIF(O17,TODAY(),"Y") -> 3 | AH17: {=_xlfn.IFS(E17>49,"50+",E17>39,"40-49",E17>29,"30-39",E17>19,"20-29")} -> 20-29 | AI17: {=_xlfn.IFS(AG17>10,"10+",AG17>4,"5-10 YIL",AG17>2,"3-5 YIL",AG17>0.9,"1-3 YIL",AG17<1,"0-1 YIL")} -> 3-5 YIL | AJ17: =YEAR(O17) -> 2022 | AK17: =YEAR(P17) -> #VALUE!
A18: PER0017 | B18: Dilan Çetin | C18: Kadın | D18: 34842 | E18: 31 | F18: Bekar | G18: 0 | H18: Lisans | I18: Satış & Pazarlama | J18: Kıdemli Satış Uzmanı | K18: Senior | L18: Beyaz Yaka | M18: Satış & Pazarlama Müdürü | N18: İstanbul Merkez | O18: 44829 | P18: - | Q18: - | R18: - | S18: Aktif | T18: 59200 | U18: 6600 | V18: 1 | W18: 27 | X18: 01-Istirahat | Y18: 3 | Z18: 7 | AA18: 0 | AB18: 0 | AC18: 3 | AD18: 5 | AE18: Kariyer.net | AG18: =DATEDIF(O18,TODAY(),"Y") -> 3 | AH18: {=_xlfn.IFS(E18>49,"50+",E18>39,"40-49",E18>29,"30-39",E18>19,"20-29")} -> 30-39 | AI18: {=_xlfn.IFS(AG18>10,"10+",AG18>4,"5-10 YIL",AG18>2,"3-5 YIL",AG18>0.9,"1-3 YIL",AG18<1,"0-1 YIL")} -> 3-5 YIL | AJ18: =YEAR(O18) -> 2022 | AK18: =YEAR(P18) -> #VALUE!
A19: PER0018 | B19: Mehmet Yılmaz | C19: Erkek | D19: 35865 | E19: 28 | F19: Bekar | G19: 0 | H19: Lisans | I19: Satış & Pazarlama | J19: Kıdemli Satış Uzmanı | K19: Senior | L19: Beyaz Yaka | M19: Satış & Pazarlama Müdürü | N19: Bursa Merkez | O19: 44978 | P19: - | Q19: - | R19: - | S19: Aktif | T19: 61300 | U19: 16100 | V19: 4 | W19: 30 | X19: - | Y19: 0 | Z19: 1 | AA19: 0 | AB19: 0 | AC19: 1 | AD19: 19 | AE19: Kariyer.net | AG19: =DATEDIF(O19,TODAY(),"Y") -> 3 | AH19: {=_xlfn.IFS(E19>49,"50+",E19>39,"40-49",E19>29,"30-39",E19>19,"20-29")} -> 20-29 | AI19: {=_xlfn.IFS(AG19>10,"10+",AG19>4,"5-10 YIL",AG19>2,"3-5 YIL",AG19>0.9,"1-3 YIL",AG19<1,"0-1 YIL")} -> 3-5 YIL | AJ19: =YEAR(O19) -> 2023 | AK19: =YEAR(P19) -> #VALUE!
A20: PER0019 | B20: Ayşe Aslan | C20: Kadın | D20: 36854 | E20: 26 | F20: Bekar | G20: 0 | H20: Önlisans | I20: Üretim & Operasyon | J20: Operatör | K20: Junior | L20: Mavi Yaka | M20: Üretim & Operasyon Müdürü | N20: Bursa Merkez | O20: 45592 | P20: - | Q20: - | R20: - | S20: Aktif | T20: 25200 | U20: 0 | V20: 19 | W20: 28 | X20: 10-Devamsizlik | Y20: 0 | Z20: 2 | AA20: 0 | AB20: 2 | AC20: 3 | AD20: 19 | AE20: LinkedIn | AG20: =DATEDIF(O20,TODAY(),"Y") -> 1 | AH20: {=_xlfn.IFS(E20>49,"50+",E20>39,"40-49",E20>29,"30-39",E20>19,"20-29")} -> 20-29 | AI20: {=_xlfn.IFS(AG20>10,"10+",AG20>4,"5-10 YIL",AG20>2,"3-5 YIL",AG20>0.9,"1-3 YIL",AG20<1,"0-1 YIL")} -> 1-3 YIL | AJ20: =YEAR(O20) -> 2024 | AK20: =YEAR(P20) -> #VALUE!
... A22: PER0021 | B22: Can Şahin | C22: Erkek | D22: 31711 | E22: 40 | F22: Evli | G22: 1 | H22: Lisans | I22: Satış & Pazarlama | J22: Kıdemli Satış Uzmanı | K22: Senior | L22: Beyaz Yaka | M22: Satış & Pazarlama Müdürü | N22: Bursa Merkez | O22: 43395 | P22: - | Q22: - | R22: - | S22: Aktif | T22: 60400 | U22: 14300 | V22: 3 | W22: 29 | X22: 01-Istirahat | Y22: 1 | Z22: 0 | AA22: 0 | AB22: 0 | AC22: 2 | AD22: 8 | AE22: Kariyer.net | AG22: =DATEDIF(O22,TODAY(),"Y") -> 7 | AH22: {=_xlfn.IFS(E22>49,"50+",E22>39,"40-49",E22>29,"30-39",E22>19,"20-29")} -> 40-49 | AI22: {=_xlfn.IFS(AG22>10,"10+",AG22>4,"5-10 YIL",AG22>2,"3-5 YIL",AG22>0.9,"1-3 YIL",AG22<1,"0-1 YIL")} -> 5-10 YIL | AJ22: =YEAR(O22) -> 2018 | AK22: =YEAR(P22) -> #VALUE!
A23: PER0022 | B23: Ecem Kaya | C23: Kadın | D23: 36697 | E23: 26 | F23: Bekar | G23: 0 | H23: Önlisans | I23: Üretim & Operasyon | J23: Operatör | K23: Junior | L23: Mavi Yaka | M23: Üretim & Operasyon Müdürü | N23: İstanbul Merkez | O23: 46029 | P23: 46062 | Q23: İstifa (Kariyer Değişikliği) | R23: 4 | S23: Pasif | T23: 27300 | U23: 0 | V23: 28 | W23: 29 | X23: 01-Istirahat | Y23: 1 | Z23: 0 | AA23: 0 | AB23: 0 | AC23: 4 | AD23: 18 | AE23: Kariyer.net | AG23: =DATEDIF(O23,TODAY(),"Y") -> 0 | AH23: {=_xlfn.IFS(E23>49,"50+",E23>39,"40-49",E23>29,"30-39",E23>19,"20-29")} -> 20-29 | AI23: {=_xlfn.IFS(AG23>10,"10+",AG23>4,"5-10 YIL",AG23>2,"3-5 YIL",AG23>0.9,"1-3 YIL",AG23<1,"0-1 YIL")} -> 0-1 YIL | AJ23: =YEAR(O23) -> 2026 | AK23: =YEAR(P23) -> 2026
A24: PER0023 | B24: Elif Kılıç | C24: Kadın | D24: 30164 | E24: 44 | F24: Evli | G24: 2 | H24: Lisans | I24: Satış & Pazarlama | J24: Kıdemli Satış Uzmanı | K24: Senior | L24: Beyaz Yaka | M24: Satış & Pazarlama Müdürü | N24: Ankara Merkez | O24: 42040 | P24: 45697 | Q24: Performans Yetersizliği | R24: 17 | S24: Pasif | T24: 58400 | U24: 0 | V24: 4 | W24: 20 | X24: 01-Istirahat | Y24: 10 | Z24: 2 | AA24: 0 | AB24: 0 | AC24: 3 | AD24: 19 | AE24: LinkedIn | AG24: =DATEDIF(O24,TODAY(),"Y") -> 11 | AH24: {=_xlfn.IFS(E24>49,"50+",E24>39,"40-49",E24>29,"30-39",E24>19,"20-29")} -> 40-49 | AI24: {=_xlfn.IFS(AG24>10,"10+",AG24>4,"5-10 YIL",AG24>2,"3-5 YIL",AG24>0.9,"1-3 YIL",AG24<1,"0-1 YIL")} -> 10+ | AJ24: =YEAR(O24) -> 2015 | AK24: =YEAR(P24) -> 2025
A25: PER0024 | B25: Kübra Kara | C25: Kadın | D25: 30114 | E25: 44 | F25: Bekar | G25: 0 | H25: Lisans | I25: Satış & Pazarlama | J25: Satış Müdürü | K25: Manager | L25: Beyaz Yaka | M25: Genel Müdür | N25: İstanbul Merkez | O25: 41635 | P25: - | Q25: - | R25: - | S25: Aktif | T25: 103300 | U25: 27000 | V25: 3 | W25: 30 | X25: - | Y25: 0 | Z25: 8 | AA25: 0 | AB25: 0 | AC25: 3 | AD25: 18 | AE25: LinkedIn | AG25: =DATEDIF(O25,TODAY(),"Y") -> 12 | AH25: {=_xlfn.IFS(E25>49,"50+",E25>39,"40-49",E25>29,"30-39",E25>19,"20-29")} -> 40-49 | AI25: {=_xlfn.IFS(AG25>10,"10+",AG25>4,"5-10 YIL",AG25>2,"3-5 YIL",AG25>0.9,"1-3 YIL",AG25<1,"0-1 YIL")} -> 10+ | AJ25: =YEAR(O25) -> 2013 | AK25: =YEAR(P25) -> #VALUE!
A26: PER0025 | B26: Selin Kılıç | C26: Kadın | D26: 38284 | E26: 22 | F26: Evli | G26: 0 | H26: Önlisans | I26: Üretim & Operasyon | J26: Operatör | K26: Junior | L26: Mavi Yaka | M26: Üretim & Operasyon Müdürü | N26: İzmir Merkez | O26: 45523 | P26: - | Q26: - | R26: - | S26: Aktif | T26: 24000 | U26: 0 | V26: 42 | W26: 29 | X26: 01-Istirahat | Y26: 1 | Z26: 14 | AA26: 0 | AB26: 0 | AC26: 3 | AD26: 18 | AE26: Referans | AG26: =DATEDIF(O26,TODAY(),"Y") -> 1 | AH26: {=_xlfn.IFS(E26>49,"50+",E26>39,"40-49",E26>29,"30-39",E26>19,"20-29")} -> 20-29 | AI26: {=_xlfn.IFS(AG26>10,"10+",AG26>4,"5-10 YIL",AG26>2,"3-5 YIL",AG26>0.9,"1-3 YIL",AG26<1,"0-1 YIL")} -> 1-3 YIL | AJ26: =YEAR(O26) -> 2024 | AK26: =YEAR(P26) -> #VALUE!
A27: PER0026 | B27: Ali Kara | C27: Erkek | D27: 26074 | E27: 55 | F27: Evli | G27: 0 | H27: Yüksek Lisans | I27: Finans & Muhasebe | J27: Finans Müdürü | K27: Manager | L27: Beyaz Yaka | M27: Genel Müdür | N27: Bursa Merkez | O27: 41992 | P27: - | Q27: - | R27: - | S27: Aktif | T27: 112800 | U27: 0 | V27: 0 | W27: 25 | X27: 01-Istirahat | Y27: 5 | Z27: 13 | AA27: 0 | AB27: 0 | AC27: 4 | AD27: 19 | AE27: Kariyer.net | AG27: =DATEDIF(O27,TODAY(),"Y") -> 11 | AH27: {=_xlfn.IFS(E27>49,"50+",E27>39,"40-49",E27>29,"30-39",E27>19,"20-29")} -> 50+ | AI27: {=_xlfn.IFS(AG27>10,"10+",AG27>4,"5-10 YIL",AG27>2,"3-5 YIL",AG27>0.9,"1-3 YIL",AG27<1,"0-1 YIL")} -> 10+ | AJ27: =YEAR(O27) -> 2014 | AK27: =YEAR(P27) -> #VALUE!
A28: PER0027 | B28: Ayşe Öztürk | C28: Kadın | D28: 32106 | E28: 39 | F28: Bekar | G28: 0 | H28: Lisans | I28: Üretim & Operasyon | J28: Takım Lideri | K28: Senior | L28: Mavi Yaka | M28: Üretim & Operasyon Müdürü | N28: Bursa Merkez | O28: 43506 | P28: - | Q28: - | R28: - | S28: Aktif | T28: 41400 | U28: 0 | V28: 30 | W28: 30 | X28: - | Y28: 0 | Z28: 6 | AA28: 0 | AB28: 0 | AC28: 1 | AD28: 7 | AE28: Kariyer.net | AG28: =DATEDIF(O28,TODAY(),"Y") -> 7 | AH28: {=_xlfn.IFS(E28>49,"50+",E28>39,"40-49",E28>29,"30-39",E28>19,"20-29")} -> 30-39 | AI28: {=_xlfn.IFS(AG28>10,"10+",AG28>4,"5-10 YIL",AG28>2,"3-5 YIL",AG28>0.9,"1-3 YIL",AG28<1,"0-1 YIL")} -> 5-10 YIL | AJ28: =YEAR(O28) -> 2019 | AK28: =YEAR(P28) -> #VALUE!
A29: PER0028 | B29: Hüseyin Doğan | C29: Erkek | D29: 37626 | E29: 23 | F29: Evli | G29: 2 | H29: Lisans | I29: Finans & Muhasebe | J29: Muhasebe Elemanı | K29: Junior | L29: Beyaz Yaka | M29: Finans & Muhasebe Müdürü | N29: İstanbul Merkez | O29: 45159 | P29: - | Q29: - | R29: - | S29: Aktif | T29: 39700 | U29: 0 | V29: 7 | W29: 30 | X29: - | Y29: 0 | Z29: 1 | AA29: 0 | AB29: 0 | AC29: 3 | AD29: 12 | AE29: Kariyer.net | AG29: =DATEDIF(O29,TODAY(),"Y") -> 2 | AH29: {=_xlfn.IFS(E29>49,"50+",E29>39,"40-49",E29>29,"30-39",E29>19,"20-29")} -> 20-29 | AI29: {=_xlfn.IFS(AG29>10,"10+",AG29>4,"5-10 YIL",AG29>2,"3-5 YIL",AG29>0.9,"1-3 YIL",AG29<1,"0-1 YIL")} -> 1-3 YIL | AJ29: =YEAR(O29) -> 2023 | AK29: =YEAR(P29) -> #VALUE!
A30: PER0029 | B30: Kübra Özdemir | C30: Kadın | D30: 38073 | E30: 22 | F30: Evli | G30: 1 | H30: Lisans | I30: Üretim & Operasyon | J30: Operatör | K30: Junior | L30: Mavi Yaka | M30: Üretim & Operasyon Müdürü | N30: Gebze Fabrika | O30: 45351 | P30: 45441 | Q30: İstifa (Kariyer Değişikliği) | R30: 4 | S30: Pasif | T30: 24000 | U30: 0 | V30: 14 | W30: 30 | X30: - | Y30: 0 | Z30: 5 | AA30: 0 | AB30: 0 | AC30: 2 | AD30: 10 | AE30: Kariyer.net | AG30: =DATEDIF(O30,TODAY(),"Y") -> 2 | AH30: {=_xlfn.IFS(E30>49,"50+",E30>39,"40-49",E30>29,"30-39",E30>19,"20-29")} -> 20-29 | AI30: {=_xlfn.IFS(AG30>10,"10+",AG30>4,"5-10 YIL",AG30>2,"3-5 YIL",AG30>0.9,"1-3 YIL",AG30<1,"0-1 YIL")} -> 1-3 YIL | AJ30: =YEAR(O30) -> 2024 | AK30: =YEAR(P30) -> 2024
A31: PER0030 | B31: Ahmet Çetin | C31: Erkek | D31: 32420 | E31: 38 | F31: Evli | G31: 1 | H31: Önlisans | I31: Satış & Pazarlama | J31: Kıdemli Satış Uzmanı | K31: Senior | L31: Beyaz Yaka | M31: Satış & Pazarlama Müdürü | N31: İstanbul Merkez | O31: 44822 | P31: - | Q31: - | R31: - | S31: Aktif | T31: 58800 | U31: 20400 | V31: 5 | W31: 30 | X31: - | Y31: 0 | Z31: 13 | AA31: 0 | AB31: 0 | AC31: 3 | AD31: 14 | AE31: LinkedIn | AG31: =DATEDIF(O31,TODAY(),"Y") -> 3 | AH31: {=_xlfn.IFS(E31>49,"50+",E31>39,"40-49",E31>29,"30-39",E31>19,"20-29")} -> 30-39 | AI31: {=_xlfn.IFS(AG31>10,"10+",AG31>4,"5-10 YIL",AG31>2,"3-5 YIL",AG31>0.9,"1-3 YIL",AG31<1,"0-1 YIL")} -> 3-5 YIL | AJ31: =YEAR(O31) -> 2022 | AK31: =YEAR(P31) -> #VALUE!
A32: PER0031 | B32: Defne Öztürk | C32: Kadın | D32: 31486 | E32: 40 | F32: Bekar | G32: 0 | H32: Yüksek Lisans | I32: Bilgi Teknolojileri | J32: BT Müdürü | K32: Manager | L32: Beyaz Yaka | M32: Genel Müdür | N32: Bursa Merkez | O32: 43426 | P32: - | Q32: - | R32: - | S32: Aktif | T32: 123100 | U32: 0 | V32: 6 | W32: 30 | X32: - | Y32: 0 | Z32: 8 | AA32: 0 | AB32: 0 | AC32: 4 | AD32: 31 | AE32: Kariyer.net | AG32: =DATEDIF(O32,TODAY(),"Y") -> 7 | AH32: {=_xlfn.IFS(E32>49,"50+",E32>39,"40-49",E32>29,"30-39",E32>19,"20-29")} -> 40-49 | AI32: {=_xlfn.IFS(AG32>10,"10+",AG32>4,"5-10 YIL",AG32>2,"3-5 YIL",AG32>0.9,"1-3 YIL",AG32<1,"0-1 YIL")} -> 5-10 YIL | AJ32: =YEAR(O32) -> 2018 | AK32: =YEAR(P32) -> #VALUE!
A33: PER0032 | B33: Ecem Aslan | C33: Kadın | D33: 37747 | E33: 23 | F33: Evli | G33: 1 | H33: Lisans | I33: Üretim & Operasyon | J33: Operatör | K33: Junior | L33: Mavi Yaka | M33: Üretim & Operasyon Müdürü | N33: Gebze Fabrika | O33: 45994 | P33: - | Q33: - | R33: - | S33: Aktif | T33: 25500 | U33: 0 | V33: 15 | W33: 30 | X33: - | Y33: 0 | Z33: 0 | AA33: 0 | AB33: 0 | AC33: 2 | AD33: 17 | AE33: LinkedIn | AG33: =DATEDIF(O33,TODAY(),"Y") -> 0 | AH33: {=_xlfn.IFS(E33>49,"50+",E33>39,"40-49",E33>29,"30-39",E33>19,"20-29")} -> 20-29 | AI33: {=_xlfn.IFS(AG33>10,"10+",AG33>4,"5-10 YIL",AG33>2,"3-5 YIL",AG33>0.9,"1-3 YIL",AG33<1,"0-1 YIL")} -> 0-1 YIL | AJ33: =YEAR(O33) -> 2025 | AK33: =YEAR(P33) -> #VALUE!
A34: PER0033 | B34: Dilan Çetin | C34: Kadın | D34: 31513 | E34: 40 | F34: Evli | G34: 2 | H34: Önlisans | I34: Üretim & Operasyon | J34: Üretim Müdürü | K34: Manager | L34: Beyaz Yaka | M34: Genel Müdür | N34: İstanbul Merkez | O34: 43979 | P34: - | Q34: - | R34: - | S34: Aktif | T34: 108800 | U34: 0 | V34: 7 | W34: 29 | X34: 01-Istirahat | Y34: 1 | Z34: 1 | AA34: 0 | AB34: 0 | AC34: 3 | AD34: 9 | AE34: Kariyer.net | AG34: =DATEDIF(O34,TODAY(),"Y") -> 6 | AH34: {=_xlfn.IFS(E34>49,"50+",E34>39,"40-49",E34>29,"30-39",E34>19,"20-29")} -> 40-49 | AI34: {=_xlfn.IFS(AG34>10,"10+",AG34>4,"5-10 YIL",AG34>2,"3-5 YIL",AG34>0.9,"1-3 YIL",AG34<1,"0-1 YIL")} -> 5-10 YIL | AJ34: =YEAR(O34) -> 2020 | AK34: =YEAR(P34) -> #VALUE!
A35: PER0034 | B35: Can Yıldız | C35: Erkek | D35: 35926 | E35: 28 | F35: Bekar | G35: 0 | H35: Lisans | I35: Satış & Pazarlama | J35: Kıdemli Satış Uzmanı | K35: Senior | L35: Beyaz Yaka | M35: Satış & Pazarlama Müdürü | N35: İstanbul Merkez | O35: 42896 | P35: - | Q35: - | R35: - | S35: Aktif | T35: 58800 | U35: 11300 | V35: 4 | W35: 27 | X35: 02-Ucretsiz Izin | Y35: 0 | Z35: 12 | AA35: 3 | AB35: 0 | AC35: 3 | AD35: 2 | AE35: LinkedIn | AG35: =DATEDIF(O35,TODAY(),"Y") -> 9 | AH35: {=_xlfn.IFS(E35>49,"50+",E35>39,"40-49",E35>29,"30-39",E35>19,"20-29")} -> 20-29 | AI35: {=_xlfn.IFS(AG35>10,"10+",AG35>4,"5-10 YIL",AG35>2,"3-5 YIL",AG35>0.9,"1-3 YIL",AG35<1,"0-1 YIL")} -> 5-10 YIL | AJ35: =YEAR(O35) -> 2017 | AK35: =YEAR(P35) -> #VALUE!
A36: PER0035 | B36: Ecem Doğan | C36: Kadın | D36: 29809 | E36: 45 | F36: Evli | G36: 1 | H36: Lisans | I36: İnsan Kaynakları | J36: İK Uzmanı | K36: Senior | L36: Beyaz Yaka | M36: İnsan Kaynakları Müdürü | N36: İstanbul Merkez | O36: 43481 | P36: - | Q36: - | R36: - | S36: Aktif | T36: 53300 | U36: 0 | V36: 7 | W36: 28 | X36: 01-Istirahat | Y36: 2 | Z36: 11 | AA36: 0 | AB36: 0 | AC36: 2 | AD36: 6 | AE36: Referans | AG36: =DATEDIF(O36,TODAY(),"Y") -> 7 | AH36: {=_xlfn.IFS(E36>49,"50+",E36>39,"40-49",E36>29,"30-39",E36>19,"20-29")} -> 40-49 | AI36: {=_xlfn.IFS(AG36>10,"10+",AG36>4,"5-10 YIL",AG36>2,"3-5 YIL",AG36>0.9,"1-3 YIL",AG36<1,"0-1 YIL")} -> 5-10 YIL | AJ36: =YEAR(O36) -> 2019 | AK36: =YEAR(P36) -> #VALUE!
A37: PER0036 | B37: Oğuzhan Çetin | C37: Erkek | D37: 37408 | E37: 24 | F37: Evli | G37: 2 | H37: Lisans | I37: Üretim & Operasyon | J37: Operatör | K37: Junior | L37: Mavi Yaka | M37: Üretim & Operasyon Müdürü | N37: Bursa Merkez | O37: 46151 | P37: - | Q37: - | R37: - | S37: Aktif | T37: 25500 | U37: 0 | V37: 11 | W37: 30 | X37: - | Y37: 0 | Z37: 0 | AA37: 0 | AB37: 0 | AC37: 2 | AD37: 7 | AE37: LinkedIn | AG37: =DATEDIF(O37,TODAY(),"Y") -> 0 | AH37: {=_xlfn.IFS(E37>49,"50+",E37>39,"40-49",E37>29,"30-39",E37>19,"20-29")} -> 20-29 | AI37: {=_xlfn.IFS(AG37>10,"10+",AG37>4,"5-10 YIL",AG37>2,"3-5 YIL",AG37>0.9,"1-3 YIL",AG37<1,"0-1 YIL")} -> 0-1 YIL | AJ37: =YEAR(O37) -> 2026 | AK37: =YEAR(P37) -> #VALUE!
A38: PER0037 | B38: Oğuzhan Çelik | C38: Erkek | D38: 33974 | E38: 33 | F38: Bekar | G38: 0 | H38: Lisans | I38: Finans & Muhasebe | J38: Mali İşler Uzmanı | K38: Senior | L38: Beyaz Yaka | M38: Finans & Muhasebe Müdürü | N38: İstanbul Merkez | O38: 41868 | P38: - | Q38: - | R38: - | S38: Aktif | T38: 61700 | U38: 7800 | V38: 0 | W38: 30 | X38: - | Y38: 0 | Z38: 14 | AA38: 0 | AB38: 0 | AC38: 4 | AD38: 35 | AE38: Kariyer.net | AG38: =DATEDIF(O38,TODAY(),"Y") -> 11 | AH38: {=_xlfn.IFS(E38>49,"50+",E38>39,"40-49",E38>29,"30-39",E38>19,"20-29")} -> 30-39 | AI38: {=_xlfn.IFS(AG38>10,"10+",AG38>4,"5-10 YIL",AG38>2,"3-5 YIL",AG38>0.9,"1-3 YIL",AG38<1,"0-1 YIL")} -> 10+ | AJ38: =YEAR(O38) -> 2014 | AK38: =YEAR(P38) -> #VALUE!
A39: PER0038 | B39: Ömer Şahin | C39: Erkek | D39: 37930 | E39: 23 | F39: Evli | G39: 1 | H39: Lisans | I39: Üretim & Operasyon | J39: Operatör | K39: Junior | L39: Mavi Yaka | M39: Üretim & Operasyon Müdürü | N39: İstanbul Merkez | O39: 45296 | P39: - | Q39: - | R39: - | S39: Aktif | T39: 28300 | U39: 0 | V39: 15 | W39: 30 | X39: - | Y39: 0 | Z39: 13 | AA39: 0 | AB39: 0 | AC39: 4 | AD39: 19 | AE39: Kariyer.net | AG39: =DATEDIF(O39,TODAY(),"Y") -> 2 | AH39: {=_xlfn.IFS(E39>49,"50+",E39>39,"40-49",E39>29,"30-39",E39>19,"20-29")} -> 20-29 | AI39: {=_xlfn.IFS(AG39>10,"10+",AG39>4,"5-10 YIL",AG39>2,"3-5 YIL",AG39>0.9,"1-3 YIL",AG39<1,"0-1 YIL")} -> 1-3 YIL | AJ39: =YEAR(O39) -> 2024 | AK39: =YEAR(P39) -> #VALUE!
A40: PER0039 | B40: Hüseyin Aydın | C40: Erkek | D40: 30707 | E40: 42 | F40: Bekar | G40: 0 | H40: Yüksek Lisans | I40: Satış & Pazarlama | J40: Satış Müdürü | K40: Manager | L40: Beyaz Yaka | M40: Genel Müdür | N40: Gebze Fabrika | O40: 41010 | P40: - | Q40: - | R40: - | S40: Aktif | T40: 119400 | U40: 39600 | V40: 5 | W40: 30 | X40: - | Y40: 0 | Z40: 3 | AA40: 0 | AB40: 0 | AC40: 2 | AD40: 2 | AE40: Referans | AG40: =DATEDIF(O40,TODAY(),"Y") -> 14 | AH40: {=_xlfn.IFS(E40>49,"50+",E40>39,"40-49",E40>29,"30-39",E40>19,"20-29")} -> 40-49 | AI40: {=_xlfn.IFS(AG40>10,"10+",AG40>4,"5-10 YIL",AG40>2,"3-5 YIL",AG40>0.9,"1-3 YIL",AG40<1,"0-1 YIL")} -> 10+ | AJ40: =YEAR(O40) -> 2012 | AK40: =YEAR(P40) -> #VALUE!
A41: PER0040 | B41: Ömer Kara | C41: Erkek | D41: 29139 | E41: 47 | F41: Evli | G41: 0 | H41: Lisans | I41: Bilgi Teknolojileri | J41: Kıdemli Yazılım Uzmanı | K41: Senior | L41: Beyaz Yaka | M41: Bilgi Teknolojileri Müdürü | N41: Bursa Merkez | O41: 41863 | P41: - | Q41: - | R41: - | S41: Aktif | T41: 76500 | U41: 0 | V41: 2 | W41: 30 | X41: - | Y41: 0 | Z41: 3 | AA41: 0 | AB41: 0 | AC41: 3 | AD41: 2 | AE41: Kariyer.net | AG41: =DATEDIF(O41,TODAY(),"Y") -> 11 | AH41: {=_xlfn.IFS(E41>49,"50+",E41>39,"40-49",E41>29,"30-39",E41>19,"20-29")} -> 40-49 | AI41: {=_xlfn.IFS(AG41>10,"10+",AG41>4,"5-10 YIL",AG41>2,"3-5 YIL",AG41>0.9,"1-3 YIL",AG41<1,"0-1 YIL")} -> 10+ | AJ41: =YEAR(O41) -> 2014 | AK41: =YEAR(P41) -> #VALUE!
...

Sheet 02_Hesaplamalar
A1: Genel Şirket Özeti
A2: Aktif Çalışan | B2: =COUNTIF('01_Personel_Verisi'!S:S,"Aktif") -> 868 | D2: Kadın Oranı % | E2: =(COUNTIFS('01_Personel_Verisi'!C:C,"Kadın",'01_Personel_Verisi'!S:S,"Aktif")/B2)*100 -> 42.857143
A3: Toplam Ayrılan | B3: =COUNTIF('01_Personel_Verisi'!S:S,"Pasif") -> 132 | D3: Ortalama Performans | E3: =AVERAGEA('01_Personel_Verisi'!AC:AC) -> 3.046953
A4: TurnOver Oranı | B4: =B3/((B2+B3+B2)/2) -> 0.14132762 | D4: Ortalama Eğitim | E4: =AVERAGEA('01_Personel_Verisi'!AD:AD) -> 14.553447
A5: Ortalama Yaş | B5: =AVERAGEIFS('01_Personel_Verisi'!E:E,'01_Personel_Verisi'!S:S,"Aktif") -> 31.813364 | D5: Aktif Çalışan Yüzdesi | E5: =(B2/(B2+B3))*100 -> 86.8
A6: Ortalama Kıdem | B6: =AVERAGEIFS('01_Personel_Verisi'!AG:AG,'01_Personel_Verisi'!S:S,"Aktif") -> 4.609447 | D6: Annualized Turnover | E6: =((COUNTIF('01_Personel_Verisi'!AK:AK,"2026"))/((B2+B2+(COUNTIF('01_Personel_Verisi'!AK:AK,"2026")))/2)*100)*2 -> 9.4488189 | F6: *Rapor tarihi haziran kabul edildi.
A7: Ortalama Maaş | B7: =AVERAGEIFS('01_Personel_Verisi'!T:T,'01_Personel_Verisi'!S:S,"Aktif") -> 48463.134
A8: Toplam Fazla Mesai | B8: =SUM('01_Personel_Verisi'!V:V) -> 15160
A9: Toplam Eksik Gün | B9: =SUM('01_Personel_Verisi'!Y:Y,'01_Personel_Verisi'!AA:AA,'01_Personel_Verisi'!AB:AB) -> 1038
A11: Departman Bazlı Analiz Matrisi | B11: Çalışan Sayısı | C11: Ortalama Maaş | D11: Toplam Fazla Mesai | E11: Ortalama Performans Notu
A12: Bilgi Teknolojileri | B12: =COUNTIFS('01_Personel_Verisi'!I:I,"Bilgi Teknolojileri",'01_Personel_Verisi'!S:S,"Aktif") -> 85 | C12: =AVERAGEIFS('01_Personel_Verisi'!T:T,'01_Personel_Verisi'!I:I,"Bilgi Teknolojileri",'01_Personel_Verisi'!S:S,"Aktif") -> 78830.588 | D12: =SUMIFS('01_Personel_Verisi'!V:V,'01_Personel_Verisi'!I:I,"Bilgi Teknolojileri") -> 498 | E12: =AVERAGEIF('01_Personel_Verisi'!I:I,"Bilgi Teknolojileri",'01_Personel_Verisi'!AC:AC) -> 3.1122449
A13: Üretim & Operasyon | B13: =COUNTIFS('01_Personel_Verisi'!I:I,"Üretim & Operasyon",'01_Personel_Verisi'!S:S,"Aktif") -> 431 | C13: =AVERAGEIFS('01_Personel_Verisi'!T:T,'01_Personel_Verisi'!I:I,"Üretim & Operasyon",'01_Personel_Verisi'!S:S,"Aktif") -> 33196.52 | D13: =SUMIFS('01_Personel_Verisi'!V:V,'01_Personel_Verisi'!I:I,"Üretim & Operasyon") -> 13137 | E13: =AVERAGEIF('01_Personel_Verisi'!I:I,"Üretim & Operasyon",'01_Personel_Verisi'!AC:AC) -> 3.0803213
A14: Satış & Pazarlama | B14: =COUNTIFS('01_Personel_Verisi'!I:I,"Satış & Pazarlama",'01_Personel_Verisi'!S:S,"Aktif") -> 176 | C14: =AVERAGEIFS('01_Personel_Verisi'!T:T,'01_Personel_Verisi'!I:I,"Satış & Pazarlama",'01_Personel_Verisi'!S:S,"Aktif") -> 57699.432 | D14: =SUMIFS('01_Personel_Verisi'!V:V,'01_Personel_Verisi'!I:I,"Satış & Pazarlama") -> 556 | E14: =AVERAGEIF('01_Personel_Verisi'!I:I,"Satış & Pazarlama",'01_Personel_Verisi'!AC:AC) -> 3.0245098
A15: İnsan Kaynakları | B15: =COUNTIFS('01_Personel_Verisi'!I:I,"İnsan Kaynakları",'01_Personel_Verisi'!S:S,"Aktif") -> 66 | C15: =AVERAGEIFS('01_Personel_Verisi'!T:T,'01_Personel_Verisi'!I:I,"İnsan Kaynakları",'01_Personel_Verisi'!S:S,"Aktif") -> 57328.788 | D15: =SUMIFS('01_Personel_Verisi'!V:V,'01_Personel_Verisi'!I:I,"İnsan Kaynakları") -> 351 | E15: =AVERAGEIF('01_Personel_Verisi'!I:I,"İnsan Kaynakları",'01_Personel_Verisi'!AC:AC) -> 2.8933333
A16: Finans & Muhasebe | B16: =COUNTIFS('01_Personel_Verisi'!I:I,"Finans & Muhasebe",'01_Personel_Verisi'!S:S,"Aktif") -> 110 | C16: =AVERAGEIFS('01_Personel_Verisi'!T:T,'01_Personel_Verisi'!I:I,"Finans & Muhasebe",'01_Personel_Verisi'!S:S,"Aktif") -> 64717.273 | D16: =SUMIFS('01_Personel_Verisi'!V:V,'01_Personel_Verisi'!I:I,"Finans & Muhasebe") -> 618 | E16: =AVERAGEIF('01_Personel_Verisi'!I:I,"Finans & Muhasebe",'01_Personel_Verisi'!AC:AC) -> 3.016
A18: Yaş Dağılımı Tablosu: | D18: Kıdem Dağılımı Tablosu
A19: 20 - 29 Yaş | B19: =COUNTIFS('01_Personel_Verisi'!AH:AH,"20-29",'01_Personel_Verisi'!S:S,"Aktif") -> 499 | D19: 0 - 1 Yıl (Yeni) | E19: =COUNTIFS('01_Personel_Verisi'!AI:AI,"0-1 YIL",'01_Personel_Verisi'!S:S,"Aktif") -> 106
A20: 30 - 39 Yaş | B20: =COUNTIFS('01_Personel_Verisi'!AH:AH,"30-39",'01_Personel_Verisi'!S:S,"Aktif") -> 174 | D20: 1 - 3 Yıl | E20: =COUNTIFS('01_Personel_Verisi'!AI:AI,"1-3 YIL",'01_Personel_Verisi'!S:S,"Aktif") -> 235
A21: 40 - 49 Yaş | B21: =COUNTIFS('01_Personel_Verisi'!AH:AH,"40-49",'01_Personel_Verisi'!S:S,"Aktif") -> 165 | D21: 3 - 5 Yıl | E21: =COUNTIFS('01_Personel_Verisi'!AI:AI,"3-5 YIL",'01_Personel_Verisi'!S:S,"Aktif") -> 187
A22: 50 Yaş ve Üstü | B22: =COUNTIFS('01_Personel_Verisi'!AH:AH,"50+",'01_Personel_Verisi'!S:S,"Aktif") -> 30 | D22: 5 - 10 Yıl | E22: =COUNTIFS('01_Personel_Verisi'!AI:AI,"5-10 YIL",'01_Personel_Verisi'!S:S,"Aktif") -> 243
D23: 10 Yıl ve Üstü | E23: =COUNTIFS('01_Personel_Verisi'!AI:AI,"10+",'01_Personel_Verisi'!S:S,"Aktif") -> 97

Sheet 03_Pivotlar
A1: Durum | B1: Aktif | G1: İşe Giriş yılı | H1: Kişi
G2: 2008 | H2: 9
A3: Departman | B3: Kişi | C3: Ortalama Brüt Maaş | G3: 2009 | H3: 9
A4: Bilgi Teknolojileri | B4: 85 | C4: 78830.588 | G4: 2010 | H4: 8
A5: Finans & Muhasebe | B5: 110 | C5: 64717.273 | G5: 2011 | H5: 12
A6: İnsan Kaynakları | B6: 66 | C6: 57328.788 | G6: 2012 | H6: 12
A7: Satış & Pazarlama | B7: 176 | C7: 57699.432 | G7: 2013 | H7: 10
A8: Üretim & Operasyon | B8: 431 | C8: 33196.52 | G8: 2014 | H8: 38
A9: Genel Toplam | B9: 868 | C9: 48463.134 | G9: 2015 | H9: 35
G10: 2016 | H10: 45
G11: 2017 | H11: 48
G12: 2018 | H12: 48
G13: 2019 | H13: 43
G14: 2020 | H14: 53
G15: 2021 | H15: 31
G16: 2022 | H16: 114
G17: 2023 | H17: 146
G18: 2024 | H18: 140
G19: 2025 | H19: 135
G20: 2026 | H20: 64
G21: Genel Toplam | H21: 1000
A27: Durum | B27: Pasif | I27: Performans Notu | J27: Ortalama Eğitim Saati
I28: 1 | J28: 11.403509
A29: Satır Etiketleri | B29: Say Sicil No | I29: 2 | J29: 10.18705
A30: Emeklilik | B30: 3 | I30: 3 | J30: 10.731978
A31: Evlilik/Taşınma | B31: 29 | I31: 4 | J31: 25.29148
A32: İstifa (Kariyer Değişikliği) | B32: 74 | I32: 5 | J32: 26.4
A33: Performans Yetersizliği | B33: 16 | I33: Genel Toplam | J33: 14.568
A34: Sağlık Sebepleri | B34: 10
A35: Genel Toplam | B35: 132

Sheet 04_Dashboard
A1: HR ANALYTICS EXECUTIVE DASHBOARD (2026)
B4: HEADCOUNT | D4: TURNOVER % | F4: ORT. YAŞ | H4: ORT. KIDEM | J4: ORT. BRÜT MAAŞ | L4: TOPLAM FM (SAAT) | N4: DEVAMSIZLIK
B5: ='02_Hesaplamalar'!B2 -> 868 | D5: ='02_Hesaplamalar'!B4 -> 0.14132762 | F5: ='02_Hesaplamalar'!B5 -> 31.813364 | H5: ='02_Hesaplamalar'!B6 -> 4.609447 | J5: ='02_Hesaplamalar'!B7 -> 48463.134 | L5: ='02_Hesaplamalar'!B8 -> 15160 | N5: ='02_Hesaplamalar'!B9 -> 1038
C8: TAHMİNİ 2026 TURNOVER : | F8: ='02_Hesaplamalar'!E6 -> 9.4488189 | G8: % | L8: KADIN ORANI : | M8: ='02_Hesaplamalar'!E2 -> 42.857143 | N8: %

Sheet 05_Dokumantasyon
A1: HR Analytics Dashboard 2026 — Proje Dokümantasyonu
A3: Bu Excel çalışma kitabı, 1000 çalışanlık kurumsal bir firmanın İnsan Kaynakları verilerini, KPI hesaplamalarını ve yönetici dashboard altyapısını içermektedir.
A4: Proje Adımları ve Sekme Yapısı:
A6: 01_Personel_Verisi | B6: 1000 satırlık birbiriyle ilişkili ve kurumsal mantığa uygun ana veri seti tabanı.
A7: 02_Hesaplamalar | B7: Dashboard alanına besleme yapacak dinamik formüller (EĞER, ÇOKETOPLA, ÇOKEĞERSAY vb.).
A8: 03_Pivotlar | B8: Dilimleyicilerle (Slicer) bağlanacak ve grafikleri besleyecek ara özet tablolar.
A9: 04_Dashboard | B9: CEO ve Üst Yönetim sunumu için tasarlanmış, üstte özet KPI kartları ve altta profesyonel grafik alanları içeren vizyon şablonu.
